Traceback (most recent call last):
  File "/Users/colbrydi/REPOS/MTH314_Textbook/envs/lib/python3.9/site-packages/jupyter_cache/executors/utils.py", line 51, in single_nb_execution
    executenb(
  File "/Users/colbrydi/REPOS/MTH314_Textbook/envs/lib/python3.9/site-packages/nbclient/client.py", line 1112, in execute
    return NotebookClient(nb=nb, resources=resources, km=km, **kwargs).execute()
  File "/Users/colbrydi/REPOS/MTH314_Textbook/envs/lib/python3.9/site-packages/nbclient/util.py", line 74, in wrapped
    return just_run(coro(*args, **kwargs))
  File "/Users/colbrydi/REPOS/MTH314_Textbook/envs/lib/python3.9/site-packages/nbclient/util.py", line 53, in just_run
    return loop.run_until_complete(coro)
  File "/Users/colbrydi/REPOS/MTH314_Textbook/envs/lib/python3.9/asyncio/base_events.py", line 642, in run_until_complete
    return future.result()
  File "/Users/colbrydi/REPOS/MTH314_Textbook/envs/lib/python3.9/site-packages/nbclient/client.py", line 553, in async_execute
    await self.async_execute_cell(
  File "/Users/colbrydi/REPOS/MTH314_Textbook/envs/lib/python3.9/site-packages/nbclient/client.py", line 857, in async_execute_cell
    self._check_raise_for_error(cell, exec_reply)
  File "/Users/colbrydi/REPOS/MTH314_Textbook/envs/lib/python3.9/site-packages/nbclient/client.py", line 760, in _check_raise_for_error
    raise CellExecutionError.from_cell_and_msg(cell, exec_reply_content)
nbclient.exceptions.CellExecutionError: An error occurred while executing the following cell:
------------------
%matplotlib inline
import matplotlib.pylab as plt
import numpy as np
import imageio

#from urllib.request import urlopen, urlretrieve
from imageio import imsave

url = 'https://res.cloudinary.com/miles-extranet-dev/image/upload/ar_16:9,c_fill,w_1000,g_face,q_50/Michigan/migration_photos/G21696/G21696-msubeaumonttower01.jpg'
im = imageio.imread(url)

im[10,10,0] = 255
im[10,10,1] = 255
im[10,10,2] = 255

#Show the image
plt.imshow(im);
------------------

[0;31m---------------------------------------------------------------------------[0m
[0;31mModuleNotFoundError[0m                       Traceback (most recent call last)
[0;32m<ipython-input-13-99e8bc3dfcbc>[0m in [0;36m<module>[0;34m[0m
[1;32m      2[0m [0;32mimport[0m [0mmatplotlib[0m[0;34m.[0m[0mpylab[0m [0;32mas[0m [0mplt[0m[0;34m[0m[0;34m[0m[0m
[1;32m      3[0m [0;32mimport[0m [0mnumpy[0m [0;32mas[0m [0mnp[0m[0;34m[0m[0;34m[0m[0m
[0;32m----> 4[0;31m [0;32mimport[0m [0mimageio[0m[0;34m[0m[0;34m[0m[0m
[0m[1;32m      5[0m [0;34m[0m[0m
[1;32m      6[0m [0;31m#from urllib.request import urlopen, urlretrieve[0m[0;34m[0m[0;34m[0m[0;34m[0m[0m

[0;31mModuleNotFoundError[0m: No module named 'imageio'
ModuleNotFoundError: No module named 'imageio'

